import asyncio
import logging
from collections.abc import AsyncGenerator
from typing import Protocol, TypeVar

T_Send = TypeVar("T_Send")

log = logging.getLogger("machinery.helpers")


class _WithRepr(Protocol):
    def __repr__(self) -> str: ...


async def stop_async_generator(
    gen: AsyncGenerator[object, T_Send | None],
    provide: T_Send | None = None,
    name: str | None = None,
    exc: BaseException | None = None,
) -> None:
    try:
        try:
            await gen.athrow(exc or asyncio.CancelledError())
        except StopAsyncIteration:
            pass

        try:
            await gen.asend(provide)
        except StopAsyncIteration:
            pass
    finally:
        await gen.aclose()


def fut_to_string(f: asyncio.Future[object] | _WithRepr, with_name: bool = True) -> str:
    if not isinstance(f, asyncio.Future):
        s = repr(f)
    else:
        s = ""
        if with_name:
            s = f"<Future#{getattr(f, 'name', None)}"
        if not f.done():
            s = f"{s}(pending)"
        elif f.cancelled():
            s = f"{s}(cancelled)"
        else:
            exc = f.exception()
            if exc:
                s = f"{s}(exception:{type(exc).__name__}:{exc})"
            else:
                s = f"{s}(result)"
        if with_name:
            s = f"{s}>"
    return s


def silent_reporter(res):
    """
    A generic reporter for asyncio tasks that doesn't log errors.

    For example:

    .. code-block:: python

        t = loop.create_task(coroutine())
        t.add_done_callback(hp.silent_reporter)

    This means that exceptions are **not** logged to the terminal and you won't
    get warnings about tasks not being looked at when they finish.

    This method will return ``True`` if there was no exception and ``None``
    otherwise.

    It also handles and silences ``asyncio.CancelledError``.
    """
    if not res.cancelled():
        exc = res.exception()
        if not exc:
            res.result()
            return True


def reporter(res):
    """
    A generic reporter for asyncio tasks.

    For example:

    .. code-block:: python

        t = loop.create_task(coroutine())
        t.add_done_callback(hp.reporter)

    This means that exceptions are logged to the terminal and you won't
    get warnings about tasks not being looked at when they finish.

    This method will return ``True`` if there was no exception and ``None``
    otherwise.

    It also handles and silences ``asyncio.CancelledError``.
    """
    if not res.cancelled():
        exc = res.exception()
        if exc:
            if not isinstance(exc, KeyboardInterrupt):
                log.exception(exc, exc_info=(type(exc), exc, exc.__traceback__))
        else:
            res.result()
            return True


def get_event_loop():
    return asyncio.get_event_loop_policy().get_event_loop()


def create_future(*, name=None, loop=None):
    if loop is None:
        loop = get_event_loop()
    future = loop.create_future()
    future.name = name
    future.add_done_callback(silent_reporter)
    return future


def fut_has_callback(fut, callback):
    """
    Look at the callbacks on the future and return ``True`` if any of them
    are the provided ``callback``.
    """
    if not fut._callbacks:
        return False

    for cb in fut._callbacks:
        if type(cb) is tuple and cb:
            cb = cb[0]

        if cb == callback:
            return True

    return False


def async_as_background(coroutine, silent=False):
    """
    Create a task with :func:`reporter` as a done callback and return the created
    task. If ``silent=True`` then use :func:`silent_reporter`.

    This is useful because if a task exits with an exception, but nothing ever
    retrieves that exception then Python will print annoying warnings about this.

    .. code-block:: python

        from machinery import helpers as hp


        async def my_func():
            await something()

        # Kick off the function in the background
        hp.async_as_background(my_func())
    """
    t = get_event_loop().create_task(coroutine)
    if silent:
        t.add_done_callback(silent_reporter)
    else:
        t.add_done_callback(reporter)
    return t


async def async_with_timeout(
    coroutine, *, timeout=10, timeout_error=None, silent=False, name=None
):
    """
    Run a coroutine as a task until it's complete or times out.

    If time runs out the task is cancelled.

    If timeout_error is defined, that is raised instead of asyncio.CancelledError
    on timeout.

    .. code-block:: python

        from machinery.helpers import hp

        import asyncio


        async def my_coroutine():
            await asyncio.sleep(120)

        await hp.async_with_timeout(my_coroutine(), timeout=20)
    """
    f = create_future(name=f"||async_with_timeout({name})[final]")
    t = async_as_background(coroutine, silent=silent)

    def pass_result(res):
        if res.cancelled():
            f.cancel()
            return

        if res.exception() is not None:
            if not f.done():
                f.set_exception(t.exception())
            return

        if t.done() and not f.done():
            f.set_result(t.result())

    t.add_done_callback(pass_result)

    def set_timeout():
        if not t.done():
            if timeout_error and not f.done():
                f.set_exception(timeout_error)

            t.cancel()
            f.cancel()

    handle = get_event_loop().call_later(timeout, set_timeout)
    try:
        return await f
    finally:
        handle.cancel()


def transfer_result(fut, errors_only=False, process=None):
    """
    Return a ``done_callback`` that transfers the result, errors or cancellation
    to the provided future.

    If errors_only is ``True`` then it will not transfer a successful result
    to the provided future.

    .. code-block:: python

        from machinery import helpers as hp

        import asyncio


        async def my_coroutine():
            return 2

        fut = hp.create_future()
        task = hp.async_as_background(my_coroutine())
        task.add_done_callback(hp.transfer_result(fut))

        assert (await fut) == 2

    If process is provided, then when the coroutine is done, process will be
    called with the result of the coroutine and the future that result is being
    transferred to.
    """

    def transfer(res):
        if res.cancelled():
            fut.cancel()
            return

        exc = res.exception()

        if fut.done():
            return

        if exc is not None:
            fut.set_exception(exc)
            return

        if not errors_only:
            fut.set_result(res.result())

        if process:
            process(res, fut)

    return transfer


def noncancelled_results_from_futs(futs):
    """
    Get back (exception, results) from a list of futures

    exception
        A single exception if all the errors are the same type
        or if there is only one exception

        otherwise it is None

    results
        A list of the results that exist
    """
    errors = []
    results = []
    for f in futs:
        if f.done() and not f.cancelled():
            exc = f.exception()
            if exc:
                if not any(e == exc for e in errors):
                    errors.append(exc)
            else:
                results.append(f.result())

    if errors:
        errors = list(errors)
        if len(errors) == 1:
            errors = errors[0]
        else:
            errors = ExceptionGroup("Futures failed", errors)
    else:
        errors = None

    return (errors, results)


def find_and_apply_result(final_fut, available_futs):
    """
    Find a result in available_futs with a result or exception and set that
    result/exception on both final_fut, and all the settable futs
    in available_futs.

    As a bonus, if final_fut is set, then we set that result/exception on
    available_futs.

    and if final_fut is cancelled, we cancel all the available futs

    Return True if we've changed final_fut
    """
    if final_fut.cancelled():
        for f in available_futs:
            f.cancel()
        return False

    if final_fut.done():
        current_exc = final_fut.exception()
        if current_exc:
            for f in available_futs:
                if not f.done():
                    f.set_exception(current_exc)
            return False

    errors, results = noncancelled_results_from_futs(available_futs)
    if errors:
        for f in available_futs:
            if not f.done() and not f.cancelled():
                f.set_exception(errors)
        if not final_fut.done():
            final_fut.set_exception(errors)
            return True
        return False

    if results:
        res = results[0]
        for f in available_futs:
            if not f.done() and not f.cancelled():
                f.set_result(res)
        if not final_fut.done():
            final_fut.set_result(res)
            return True
        return False

    for f in available_futs:
        if f.cancelled():
            final_fut.cancel()
            return True

    return False
